Traceback (most recent call last):
  File "/global/homes/m/mphagen/functional-connectivity/connectome-comparison/scripts/processing/extract_timeseries.py", line 160, in <module>
    assert len(rest_scans) > 0 
           ^^^^^^^^^^^^^^^^^^^
AssertionError
Traceback (most recent call last):
  File "/global/homes/m/mphagen/functional-connectivity/connectome-comparison/scripts/processing/extract_timeseries.py", line 181, in <module>
    dl.get(file, dataset=path_dict['dataset_path'])
  File "/global/homes/m/mphagen/miniconda3/envs/xcpd/lib/python3.12/site-packages/datalad/interface/base.py", line 772, in eval_func
    return return_func(*args, **kwargs)
           ^^^^^^^^^^^^^^^^^^^^^^^^^^^^
  File "/global/homes/m/mphagen/miniconda3/envs/xcpd/lib/python3.12/site-packages/datalad/interface/base.py", line 762, in return_func
    results = list(results)
              ^^^^^^^^^^^^^
  File "/global/homes/m/mphagen/miniconda3/envs/xcpd/lib/python3.12/site-packages/datalad_next/patches/interface_utils.py", line 287, in _execute_command_
    raise IncompleteResultsError(
datalad.support.exceptions.IncompleteResultsError: Command did not complete successfully. 1 failed:
[{'action': 'get',
  'annexkey': 'MD5E-s438784352--138d3ee2ebee8220095caf58ef7e5fd0.nii',
  'error_message': "Failed to download from any of 1 locations ['Failed to "
                   'acquire lock to establish download session at '
                   '/global/homes/m/mphagen/.cache/datalad/locks/downloader-auth.lck '
                   'in 3 attempts.Another process is using it (failed to '
                   "determine one)?']",
  'path': '/pscratch/sd/m/mphagen/hcp-functional-connectivity/153126/MNINonLinear/Results/rfMRI_REST1_RL/rfMRI_REST1_RL_Atlas_hp2000_clean.dtseries.nii',
  'refds': '/pscratch/sd/m/mphagen/hcp-functional-connectivity',
  'status': 'error',
  'type': 'file'}]
Traceback (most recent call last):
  File "/global/homes/m/mphagen/functional-connectivity/connectome-comparison/scripts/processing/extract_timeseries.py", line 181, in <module>
    dl.get(file, dataset=path_dict['dataset_path'])
  File "/global/homes/m/mphagen/miniconda3/envs/xcpd/lib/python3.12/site-packages/datalad/interface/base.py", line 772, in eval_func
    return return_func(*args, **kwargs)
           ^^^^^^^^^^^^^^^^^^^^^^^^^^^^
  File "/global/homes/m/mphagen/miniconda3/envs/xcpd/lib/python3.12/site-packages/datalad/interface/base.py", line 762, in return_func
    results = list(results)
              ^^^^^^^^^^^^^
  File "/global/homes/m/mphagen/miniconda3/envs/xcpd/lib/python3.12/site-packages/datalad_next/patches/interface_utils.py", line 287, in _execute_command_
    raise IncompleteResultsError(
datalad.support.exceptions.IncompleteResultsError: Command did not complete successfully. 1 failed:
[{'action': 'get',
  'annexkey': 'MD5E-s438784352--a116090fc4ee28fbde878bbce275729a.nii',
  'error_message': "Failed to download from any of 1 locations ['Failed to "
                   'acquire lock to establish download session at '
                   '/global/homes/m/mphagen/.cache/datalad/locks/downloader-auth.lck '
                   'in 3 attempts.Another process is using it (failed to '
                   "determine one)?']",
  'path': '/pscratch/sd/m/mphagen/hcp-functional-connectivity/822244/MNINonLinear/Results/rfMRI_REST1_RL/rfMRI_REST1_RL_Atlas_hp2000_clean.dtseries.nii',
  'refds': '/pscratch/sd/m/mphagen/hcp-functional-connectivity',
  'status': 'error',
  'type': 'file'}]
srun: error: nid004480: task 0: Exited with exit code 3
srun: Terminating StepId=42055947.0
